Workbook
Name Database_MISC: Misc!$A$1:$K$7
Name Database_Opponent_Games: 'Opponent Game by Game Scores'!$A$4:$G$112
Name Database_Opponent_Games_Handicap: 'Opponent Game by Game Scores'!$J$4:$P$112
Name Database_Q1: Misc!$A$15:$F$20
Name Database_Q2: Misc!$A$26:$F$31
Name Database_Q3: Misc!$A$37:$F$42
Name Database_Q4: Misc!$A$48:$G$53
Name Database_Team_Games: 'Eric Stat'!$A$4:$F$4
Name Database_Team_Games: 'Game by Game Scores'!$A$4:$G$112
Name Database_Team_Games_Handicap: 'Eric Stat'!#REF!
Name Database_Team_Games_Handicap: 'Game by Game Scores'!$J$4:$P$112
Name Team_Games: 'Eric Stat'!$A$4:$A$4
Name Team_Games: 'Game by Game Scores'!$A$4:$A$112
Name Team_Games_Handicap: 'Eric Stat'!#REF!
Name Team_Games_Handicap: 'Game by Game Scores'!$J$4:$J$112

Sheet 2026-2027 Season
A2: Bowler | B2: Head to Head Record | D2: Current Average | E2: AVG Booster | F2: Pins Diff: w/ Handicap | G2: Pins Diff: | H2: Opp. AVG | I2: Card Game Totals | J2: Card Game Win % | K2: Total Dues Paid | L2: Remaining Balance | M2: 2023 AVG | N2: 2024 AVG | O2: 2025 AVG
A3: John | B3: (5-1) | C3: =Misc!J2/(Misc!I2*3) -> 0.83333333 | D3: =Misc!B2/(Misc!I2*3) -> 209.5 | E3: =210*(3*3)-(Misc!B2) -> 633 | F3: =Misc!D2-Misc!E2 -> 59 | G3: =Misc!B2-Misc!C2 -> -49 | H3: =AVERAGE('Opponents Average'!B2:B37) -> 219.5 | I3: =SUM('Card Game'!B2:B109) -> 1 | J3: =I3/((Misc!I2)*3) -> 0.16666667 | K3: =SUM(WeeklyDues!B$2:B$37) -> 0 | L3: =1260-K3 -> 1260 | M3: 186 | N3: 192 | O3: 197
A4: Nick | B4: (3-6) | C4: =Misc!J3/(Misc!I3*3) -> 0.33333333 | D4: =Misc!B3/(Misc!I3*3) -> 202.22222 | E4: =203*(4*3)-(Misc!B3) -> 616 | F4: =Misc!D3-Misc!E3 -> -47 | G4: =Misc!B3-Misc!C3 -> -89 | H4: =AVERAGE('Opponents Average'!C2:C37) -> 197.66667 | I4: =SUM('Card Game'!C2:C109) -> 1 | J4: =I4/((Misc!I3)*3) -> 0.11111111 | K4: =SUM(WeeklyDues!C$2:C$37) -> 0 | L4: =1260-K4 -> 1260 | M4: 197 | N4: 191 | O4: 192
A5: Mike | B5: (6-3) | C5: =Misc!J4/(Misc!I4*3) -> 0.66666667 | D5: =Misc!B4/(Misc!I4*3) -> 208.88889 | E5: =209*(4*3)-(Misc!B4) -> 628 | F5: =Misc!D4-Misc!E4 -> 97 | G5: =Misc!B4-Misc!C4 -> 103 | H5: =AVERAGE('Opponents Average'!D2:D37) -> 201.33333 | I5: =SUM('Card Game'!D2:D109) -> 2 | J5: =I5/((Misc!I4)*3) -> 0.22222222 | K5: =SUM(WeeklyDues!D$2:D$37) -> 0 | L5: =1260-K5 -> 1260 | M5: 184 | N5: 193 | O5: 203
A6: Eric | B6: (4-5) | C6: =Misc!J5/(Misc!I5*3) -> 0.44444444 | D6: =Misc!B5/(Misc!I5*3) -> 197.44444 | E6: =198*(4*3)-(Misc!B5) -> 599 | F6: =Misc!D5-Misc!E5 -> -67 | G6: =Misc!B5-Misc!C5 -> -64 | H6: =AVERAGE('Opponents Average'!E2:E37) -> 201 | I6: =SUM('Card Game'!E2:E109) -> 3 | J6: =I6/((Misc!I5)*3) -> 0.33333333 | K6: =SUM(WeeklyDues!E$2:E$37) -> 0 | L6: =1260-K6 -> 1260 | M6: 199 | N6: 199 | O6: 202
A7: Greenman | B7: (4-2) | C7: =Misc!J6/(Misc!I6*3) -> 0.66666667 | D7: =Misc!B6/(Misc!I6*3) -> 179.66667 | E7: =180*(3*3)-(Misc!B6) -> 542 | F7: =Misc!D6-Misc!E6 -> -24 | G7: =Misc!B6-Misc!C6 -> -36 | H7: =AVERAGE('Opponents Average'!F2:F37) -> 195 | I7: =SUM('Card Game'!F2:F109) -> 0 | J7: =I7/((Misc!I6)*3) -> 0 | K7: =SUM(WeeklyDues!F$2:F$37) -> 0 | L7: =1260-K7 -> 1260 | M7: N/A | N7: 189 | O7: 192
A8: Ron | B8: (1-2) | C8: =SUM(Ron!C1:C100)/(Ron!L2*3) -> 0.33333333 | D8: =AVERAGE(Ron!B1:B100) -> 192.33333 | E8: =193*(2*3)-(Misc!B7) -> 581 | F8: =SUM(Ron!H2:H100)-SUM(Ron!I2:I100) -> -9 | G8: =SUM(Ron!B2:B100)-SUM(Ron!D2:D100) -> 63 | H8: =AVERAGE(Ron!G2:G100) -> 164 | I8: =SUM('Card Game'!G2:G109) -> 1 | J8: =I8/((Misc!I7)*3) -> 0.33333333 | M8: 185 | N8: 220 | O8: 195
A11: Team Average by Game | C11: Bowler Average by Game | H11: Percentage Bowled Over AVG | K11: Opponent Percentage Bowled Over AVG
A12: Game 1 Average | C12: Bowler | D12: Game 1 Average | E12: Game 2 Average | F12: Game 3 Average | H12: Bowler | I12: Percentage | K12: Bowler | L12: Percentage
A13: {=SUM('Team Totals'!B2,'Team Totals'!B5,'Team Totals'!B8,'Team Totals'!B11,'Team Totals'!B14,'Team Totals'!B17,'Team Totals'!B20,'Team Totals'!B23,'Team Totals'!B26,'Team Totals'!B29,'Team Totals'!B32,'Team Totals'!B35,'Team Totals'!B38,'Team Totals'!B41,'Team Totals'!B44,'Team Totals'!B47,'Team Totals'!B50,'Team Totals'!B53,'Team Totals'!B56,'Team Totals'!B59,'Team Totals'!B62,'Team Totals'!B65,'Team Totals'!B68,'Team Totals'!B71,'Team Totals'!B74,'Team Totals'!B77,'Team Totals'!B80,'Team Totals'!B83,'Team Totals'!B86,'Team Totals'!B89,'Team Totals'!B92,'Team Totals'!B95,'Team Totals'!B98,'Team Totals'!B101,'Team Totals'!B104,'Team Totals'!B107)/'Team Totals'!H4:I4} -> 1032.6667 | B13: #DIV/0! | C13: John | D13: =Misc!F2 -> 236 | E13: =Misc!G2 -> 192 | F13: =Misc!H2 -> 200.5 | H13: John | I13: =(SUM('Over Average Percent'!B2:B37))/(Misc!I2*3) -> 0.83333333 | K13: John | L13: =(SUM('Over Average Percent'!L2:L37))/(Misc!I2*3) -> 0.33333333
A14: Game 2 Average | C14: Nick | D14: =Misc!F3 -> 193 | E14: =Misc!G3 -> 208.66667 | F14: =Misc!H3 -> 205 | H14: Nick | I14: =(SUM('Over Average Percent'!C2:C37))/(Misc!I3*3) -> 0.66666667 | K14: Nick | L14: =(SUM('Over Average Percent'!M2:M37))/(Misc!$I$3*3) -> 0.66666667
A15: {=SUM('Team Totals'!B3,'Team Totals'!B6,'Team Totals'!B9,'Team Totals'!B12,'Team Totals'!B15,'Team Totals'!B18,'Team Totals'!B21,'Team Totals'!B24,'Team Totals'!B27,'Team Totals'!B30,'Team Totals'!B33,'Team Totals'!B36,'Team Totals'!B39,'Team Totals'!B42,'Team Totals'!B45,'Team Totals'!B48,'Team Totals'!B51,'Team Totals'!B54,'Team Totals'!B57,'Team Totals'!B60,'Team Totals'!B63,'Team Totals'!B66,'Team Totals'!B69,'Team Totals'!B72,'Team Totals'!B75,'Team Totals'!B78,'Team Totals'!B81,'Team Totals'!B84,'Team Totals'!B87,'Team Totals'!B90,'Team Totals'!B93,'Team Totals'!B96,'Team Totals'!B99,'Team Totals'!B102,'Team Totals'!B105,'Team Totals'!B108)/'Team Totals'!H4:I4} -> 986.66667 | B15: #DIV/0! | C15: Mike | D15: =Misc!F4 -> 211.66667 | E15: =Misc!G4 -> 202.66667 | F15: =Misc!H4 -> 212.33333 | H15: Mike | I15: =(SUM('Over Average Percent'!D2:D37))/(Misc!I4*3) -> 0.66666667 | K15: Mike | L15: =(SUM('Over Average Percent'!N2:N37))/(Misc!$I$4*3) -> 0.33333333
A16: Game 3 Average | C16: Eric | D16: =Misc!F5 -> 202.66667 | E16: =Misc!G5 -> 193 | F16: =Misc!H5 -> 196.66667 | H16: Eric | I16: =(SUM('Over Average Percent'!E2:E37))/(Misc!I5*3) -> 0.33333333 | K16: Eric | L16: =(SUM('Over Average Percent'!O2:O37))/(Misc!$I$5*3) -> 0.33333333
A17: {=SUM('Team Totals'!B4,'Team Totals'!B7,'Team Totals'!B10,'Team Totals'!B13,'Team Totals'!B16,'Team Totals'!B19,'Team Totals'!B22,'Team Totals'!B25,'Team Totals'!B28,'Team Totals'!B31,'Team Totals'!B34,'Team Totals'!B37,'Team Totals'!B40,'Team Totals'!B43,'Team Totals'!B46,'Team Totals'!B49,'Team Totals'!B52,'Team Totals'!B55,'Team Totals'!B58,'Team Totals'!B61,'Team Totals'!B64,'Team Totals'!B67,'Team Totals'!B70,'Team Totals'!B73,'Team Totals'!B76,'Team Totals'!B79,'Team Totals'!B82,'Team Totals'!B85,'Team Totals'!B88,'Team Totals'!B91,'Team Totals'!B94,'Team Totals'!B97,'Team Totals'!B100,'Team Totals'!B103,'Team Totals'!B106,'Team Totals'!B109)/'Team Totals'!H4:I4} -> 1008.3333 | B17: #DIV/0! | C17: Greenman | D17: =Misc!F6 -> 181.5 | E17: =Misc!G6 -> 168.5 | F17: =Misc!H6 -> 189 | H17: Greenman | I17: =(SUM('Over Average Percent'!F2:F37))/(Misc!I6*3) -> 0.33333333 | K17: Greenman | L17: =(SUM('Over Average Percent'!P2:P37))/(Misc!$I$6*3) -> 0.33333333
H18: Ron | I18: =(SUM('Over Average Percent'!G2:G37))/(Misc!I7*3) -> 0.33333333 | K18: Ron | L18: =(SUM('Over Average Percent'!Q2:Q37))/(Misc!$I$7*3) -> 1
A20: Q1 | I20: Total Winnings Earned | K20: Winnings for Each
A21: Bowler | B21: Average | C21: W/L Ratio | D21: High Game | E21: Low Game | F21: High Series | G21: Low Series | I21: =(Winnings!B38*8.5) -> 357 | K21: =(Winnings!B38*8.5)/5 -> 71.4
A22: John | B22: =Misc!B16 -> 209.5 | C22: =Misc!G16 -> (5-1) | D22: =Misc!C16 -> 247 | E22: =Misc!D16 -> 182 | F22: =Misc!E16 -> 647 | G22: =Misc!F16 -> 610
A23: Nick | B23: =Misc!B17 -> 202.22222 | C23: =Misc!G17 -> (3-6) | D23: =Misc!C17 -> 237 | E23: =Misc!D17 -> 183 | F23: =Misc!E17 -> 658 | G23: =Misc!F17 -> 594 | I23: Bowler | J23: 400 Series | K23: 500 Series | L23: 600 Series | M23: 700 Series
A24: Mike | B24: =Misc!B18 -> 208.88889 | C24: =Misc!G18 -> (6-3) | D24: =Misc!C18 -> 237 | E24: =Misc!D18 -> 169 | F24: =Misc!E18 -> 683 | G24: =Misc!F18 -> 559 | I24: John | J24: =COUNTIFS('Week by Week Scores'!B5:B40,">399",'Week by Week Scores'!B5:B40,"<500") -> 0 | K24: =COUNTIFS('Week by Week Scores'!B5:B40,">499",'Week by Week Scores'!B5:B40,"<600") -> 0 | L24: =COUNTIFS('Week by Week Scores'!B5:B40,">599",'Week by Week Scores'!B5:B40,"<700") -> 2 | M24: =COUNTIFS('Week by Week Scores'!B5:B40,">699",'Week by Week Scores'!B5:B40,"<800") -> 0
A25: Eric | B25: =Misc!B19 -> 197.44444 | C25: =Misc!G19 -> (4-5) | D25: =Misc!C19 -> 268 | E25: =Misc!D19 -> 147 | F25: =Misc!E19 -> 639 | G25: =Misc!F19 -> 580 | I25: Nick | J25: =COUNTIFS('Week by Week Scores'!C5:C40,">399",'Week by Week Scores'!C5:C40,"<500") -> 0 | K25: =COUNTIFS('Week by Week Scores'!C5:C40,">499",'Week by Week Scores'!C5:C40,"<600") -> 2 | L25: =COUNTIFS('Week by Week Scores'!C5:C40,">599",'Week by Week Scores'!C5:C40,"<700") -> 1 | M25: =COUNTIFS('Week by Week Scores'!C5:C40,">699",'Week by Week Scores'!C5:C40,"<800") -> 0
A26: Greenman | B26: =Misc!B20 -> 179.66667 | C26: =Misc!G20 -> (4-2) | D26: =Misc!C20 -> 220 | E26: =Misc!D20 -> 143 | F26: =Misc!E20 -> 580 | G26: =Misc!F20 -> 498 | I26: Mike | J26: =COUNTIFS('Week by Week Scores'!D5:D40,">399",'Week by Week Scores'!D5:D40,"<500") -> 0 | K26: =COUNTIFS('Week by Week Scores'!D5:D40,">499",'Week by Week Scores'!D5:D40,"<600") -> 1 | L26: =COUNTIFS('Week by Week Scores'!D5:D40,">599",'Week by Week Scores'!D5:D40,"<700") -> 2 | M26: =COUNTIFS('Week by Week Scores'!D5:D40,">699",'Week by Week Scores'!D5:D40,"<800") -> 0
I27: Eric | J27: =COUNTIFS('Week by Week Scores'!E5:E40,">399",'Week by Week Scores'!E5:E40,"<500") -> 0 | K27: =COUNTIFS('Week by Week Scores'!E5:E40,">499",'Week by Week Scores'!E5:E40,"<600") -> 2 | L27: =COUNTIFS('Week by Week Scores'!E5:E40,">599",'Week by Week Scores'!E5:E40,"<700") -> 1 | M27: =COUNTIFS('Week by Week Scores'!E5:E40,">699",'Week by Week Scores'!E5:E40,"<800") -> 0
A28: Q2 | I28: Greenman | J28: =COUNTIFS('Week by Week Scores'!F5:F40,">399",'Week by Week Scores'!F5:F40,"<500") -> 1 | K28: =COUNTIFS('Week by Week Scores'!F5:F40,">499",'Week by Week Scores'!F5:F40,"<600") -> 1 | L28: =COUNTIFS('Week by Week Scores'!F5:F40,">599",'Week by Week Scores'!F5:F40,"<700") -> 0 | M28: =COUNTIFS('Week by Week Scores'!F5:F40,">699",'Week by Week Scores'!F5:F40,"<800") -> 0
A29: Bowler | B29: Average | C29: W/L Ratio | D29: High Game | E29: Low Game | F29: High Series | G29: Low Series
A30: John | B30: =Misc!B27 -> #DIV/0! | C30: =Misc!G27 -> 0 | D30: =Misc!C27 -> 0 | E30: =Misc!D27 -> 0 | F30: =Misc!E27 -> 0 | G30: =Misc!F27 -> 0 | I30: Bowler | J30: <150 | K30: 150-199 | L30: 200-249 | M30: 250+
A31: Nick | B31: =Misc!B28 -> #DIV/0! | C31: =Misc!G28 -> 0 | D31: =Misc!C28 -> 0 | E31: =Misc!D28 -> 0 | F31: =Misc!E28 -> 0 | G31: =Misc!F28 -> 0 | I31: John | J31: =COUNTIF('Game by Game Scores'!B5:B112,"<150") -> 0 | K31: =COUNTIFS('Game by Game Scores'!$B$5:$B$112,">149",'Game by Game Scores'!$B$5:$B$112,"<200") -> 2 | L31: =COUNTIFS('Game by Game Scores'!$B$5:$B$112,">199",'Game by Game Scores'!$B$5:$B$112,"<250") -> 4 | M31: =COUNTIF('Game by Game Scores'!$B$5:$B$112,">249") -> 0
A32: Mike | B32: =Misc!B29 -> #DIV/0! | C32: =Misc!G29 -> 0 | D32: =Misc!C29 -> 0 | E32: =Misc!D29 -> 0 | F32: =Misc!E29 -> 0 | G32: =Misc!F29 -> 0 | I32: Nick | J32: =COUNTIF('Game by Game Scores'!C5:C112,"<150") -> 0 | K32: =COUNTIFS('Game by Game Scores'!$C$5:$C$112,">149",'Game by Game Scores'!$C$5:$C$112,"<200") -> 3 | L32: =COUNTIFS('Game by Game Scores'!$C$5:$C$112,">199",'Game by Game Scores'!$C$5:$C$112,"<250") -> 6 | M32: =COUNTIF('Game by Game Scores'!$C$5:$C$112,">249") -> 0
A33: Eric | B33: =Misc!B30 -> #DIV/0! | C33: =Misc!G30 -> 0 | D33: =Misc!C30 -> 0 | E33: =Misc!D30 -> 0 | F33: =Misc!E30 -> 0 | G33: =Misc!F30 -> 0 | I33: Mike | J33: =COUNTIF('Game by Game Scores'!D5:D112,"<150") -> 0 | K33: =COUNTIFS('Game by Game Scores'!$D$5:$D$112,">149",'Game by Game Scores'!$D$5:$D$112,"<200") -> 2 | L33: =COUNTIFS('Game by Game Scores'!$D$5:$D$112,">199",'Game by Game Scores'!$D$5:$D$112,"<250") -> 7 | M33: =COUNTIF('Game by Game Scores'!$D$5:$D$112,">249") -> 0
A34: Greenman | B34: =Misc!B31 -> #DIV/0! | C34: =Misc!G31 -> 0 | D34: =Misc!C31 -> 0 | E34: =Misc!D31 -> 0 | F34: =Misc!E31 -> 0 | G34: =Misc!F31 -> 0 | I34: Eric | J34: =COUNTIF('Game by Game Scores'!E5:E112,"<150") -> 1 | K34: =COUNTIFS('Game by Game Scores'!$E$5:$E$112,">149",'Game by Game Scores'!$E$5:$E$112,"<200") -> 4 | L34: =COUNTIFS('Game by Game Scores'!$E$5:$E$112,">199",'Game by Game Scores'!$E$5:$E$112,"<250") -> 3 | M34: =COUNTIF('Game by Game Scores'!$E$5:$E$112,">249") -> 1
I35: Greenman | J35: =COUNTIF('Game by Game Scores'!F5:F112,"<150") -> 1 | K35: =COUNTIFS('Game by Game Scores'!$F$5:$F$112,">149",'Game by Game Scores'!$F$5:$F$112,"<200") -> 3 | L35: =COUNTIFS('Game by Game Scores'!$F$5:$F$112,">199",'Game by Game Scores'!$F$5:$F$112,"<250") -> 2 | M35: =COUNTIF('Game by Game Scores'!$F$5:$F$112,">249") -> 0
A36: Q3
A37: Bowler | B37: Average | C37: W/L Ratio | D37: High Game | E37: Low Game | F37: High Series | G37: Low Series | I37: Bowler | J37: Strikes | K37: Spares | L37: Strike Per Game | M37: Spare % | N37: Splits | O37: Split %
A38: John | B38: =Misc!B38 -> #DIV/0! | C38: =Misc!G38 -> 0 | D38: =Misc!C38 -> 0 | E38: =Misc!D38 -> 0 | F38: =Misc!E38 -> 0 | G38: =Misc!F38 -> 0 | I38: John | J38: =SUM(Strikes!B2:B2) -> 34 | K38: =SUM(Spares!B6:B6) -> 23 | L38: =J38/(Misc!I2*3) -> 5.6666667 | M38: =Spares!B6/(Spares!B6+Spares!J6) -> 0.74193548 | N38: =SUM(Splits!B2:B2) -> 5 | O38: =COUNTIFS(FramebyFrame!B2:B1151,"*Spare (Split)*")/N38 -> 0.2
A39: Nick | B39: =Misc!B39 -> #DIV/0! | C39: =Misc!G39 -> 0 | D39: =Misc!C39 -> 0 | E39: =Misc!D39 -> 0 | F39: =Misc!E39 -> 0 | G39: =Misc!F39 -> 0 | I39: Nick | J39: =SUM(Strikes!C2:C2) -> 49 | K39: =SUM(Spares!C6:C6) -> 40 | L39: =J39/(Misc!I3*3) -> 5.4444444 | M39: =Spares!C6/(Spares!C6+Spares!K6) -> 0.81632653 | N39: =SUM(Splits!C2:C2) -> 6 | O39: =COUNTIFS(FramebyFrame!C2:C1151,"*Spare (Split)*")/N39 -> 0.33333333
A40: Mike | B40: =Misc!B40 -> #DIV/0! | C40: =Misc!G40 -> 0 | D40: =Misc!C40 -> 0 | E40: =Misc!D40 -> 0 | F40: =Misc!E40 -> 0 | G40: =Misc!F40 -> 0 | I40: Mike | J40: =SUM(Strikes!D2:D2) -> 56 | K40: =SUM(Spares!D6:D6) -> 30 | L40: =J40/(Misc!I4*3) -> 6.2222222 | M40: =Spares!D6/(Spares!D6+Spares!L6) -> 0.68181818 | N40: =SUM(Splits!D2:D2) -> 9 | O40: =COUNTIFS(FramebyFrame!D2:D1151,"*Spare (Split)*")/N40 -> 0.55555556
A41: Eric | B41: =Misc!B41 -> #DIV/0! | C41: =Misc!G41 -> 0 | D41: =Misc!C41 -> 0 | E41: =Misc!D41 -> 0 | F41: =Misc!E41 -> 0 | G41: =Misc!F41 -> 0 | I41: Eric | J41: =SUM(Strikes!E2:E2) -> 53 | K41: =SUM(Spares!E6:E6) -> 23 | L41: =J41/(Misc!I5*3) -> 5.8888889 | M41: =Spares!E6/(Spares!E6+Spares!M6) -> 0.51111111 | N41: =SUM(Splits!E2:E2) -> 15 | O41: =COUNTIFS(FramebyFrame!E2:E1151,"*Spare (Split)*")/N41 -> 0.13333333
A42: Greenman | B42: =Misc!B42 -> #DIV/0! | C42: =Misc!G42 -> 0 | D42: =Misc!C42 -> 0 | E42: =Misc!D42 -> 0 | F42: =Misc!E42 -> 0 | G42: =Misc!F42 -> 0 | I42: Greenman | J42: =SUM(Strikes!F2:F2) -> 32 | K42: =SUM(Spares!F6:F6) -> 18 | L42: =J42/(Misc!I6*3) -> 5.3333333 | M42: =Spares!F6/(Spares!F6+Spares!N6) -> 0.51428571 | N42: =SUM(Splits!F2:F2) -> 6 | O42: =COUNTIFS(FramebyFrame!F2:F1151,"*Spare (Split)*")/N42 -> 0.16666667
A44: Q4 | I44: Bowler | J44: Frame 1 | K44: Frame 10 | M44: Bowler | N44: 10 Pin %
A45: Bowler | B45: Average | C45: W/L Ratio | D45: High Game | E45: Low Game | F45: High Series | G45: Low Series | I45: John | J45: =DSUM(Table1[[#All],[Bowler]:[Frame 9]],J44,I44:I45) -> 9.8333333 | K45: ='FramebyFrame Totals'!T17 -> 21.166667 | M45: John | N45: =AVERAGE('10,7 Pins %'!B2:B2) -> 0.75
...

Sheet Week by Week Scores
C2: Without Handicap | L2: With Handicap
B4: John | C4: Nick | D4: Mike | E4: Eric | F4: Greenman | G4: Ron | K4: John | L4: Nick | M4: Mike | N4: Eric | O4: Greenman | P4: Ron
A5: Week 1 | B5: =SUM('Game by Game Scores'!B5:B7) -> 647 | C5: =SUM('Game by Game Scores'!C5:C7) -> 658 | D5: =SUM('Game by Game Scores'!D5:D7) -> 559 | E5: =SUM('Game by Game Scores'!E5:E7) -> 639 | F5: =SUM('Game by Game Scores'!F5:F7) -> 580 | J5: Week 1 | K5: =SUM('Game by Game Scores'!K5:K7) -> 707 | L5: =SUM('Game by Game Scores'!L5:L7) -> 658 | M5: =SUM('Game by Game Scores'!M5:M7) -> 559 | N5: =SUM('Game by Game Scores'!N5:N7) -> 639 | O5: =SUM('Game by Game Scores'!O5:O7) -> 592
A6: Week 2 | B6: =SUM('Game by Game Scores'!B8:B10) -> 610 | C6: =SUM('Game by Game Scores'!C8:C10) -> 594 | D6: =SUM('Game by Game Scores'!D8:D10) -> 683 | E6: =SUM('Game by Game Scores'!E8:E10) -> 580 | F6: =SUM('Game by Game Scores'!F8:F10) -> 498 | J6: Week 2 | K6: =SUM('Game by Game Scores'!K8:K10) -> 658 | L6: =SUM('Game by Game Scores'!L8:L10) -> 594 | M6: =SUM('Game by Game Scores'!M8:M10) -> 683 | N6: =SUM('Game by Game Scores'!N8:N10) -> 592 | O6: =SUM('Game by Game Scores'!O8:O10) -> 498
A7: Week 3 | C7: =SUM('Game by Game Scores'!C11:C13) -> 568 | D7: =SUM('Game by Game Scores'!D11:D13) -> 638 | E7: =SUM('Game by Game Scores'!E11:E13) -> 558 | G7: =SUM('Game by Game Scores'!G11:G13) -> 577 | J7: Week 3 | L7: =SUM('Game by Game Scores'!L11:L13) -> 628 | M7: =SUM('Game by Game Scores'!M11:M13) -> 638 | N7: =SUM('Game by Game Scores'!N11:N13) -> 558 | P7: =SUM('Game by Game Scores'!P11:P13) -> 577
A8: Week 4 | B8: =SUM('Game by Game Scores'!B14:B16) -> 0 | C8: =SUM('Game by Game Scores'!C14:C16) -> 0 | D8: =SUM('Game by Game Scores'!D14:D16) -> 0 | E8: =SUM('Game by Game Scores'!E14:E16) -> 0 | F8: =SUM('Game by Game Scores'!F14:F16) -> 0 | G8: =SUM('Game by Game Scores'!G14:G16) -> 0 | J8: Week 4 | K8: =SUM('Game by Game Scores'!K14:K16) -> 0 | L8: =SUM('Game by Game Scores'!L14:L16) -> 0 | M8: =SUM('Game by Game Scores'!M14:M16) -> 0 | N8: =SUM('Game by Game Scores'!N14:N16) -> 0 | O8: =SUM('Game by Game Scores'!O14:O16) -> 0 | P8: =SUM('Game by Game Scores'!P14:P16) -> 0
A9: Week 5 | B9: =SUM('Game by Game Scores'!B17:B19) -> 0 | C9: =SUM('Game by Game Scores'!C17:C19) -> 0 | D9: =SUM('Game by Game Scores'!D17:D19) -> 0 | E9: =SUM('Game by Game Scores'!E17:E19) -> 0 | F9: =SUM('Game by Game Scores'!F17:F19) -> 0 | G9: =SUM('Game by Game Scores'!G17:G19) -> 0 | J9: Week 5 | K9: =SUM('Game by Game Scores'!K17:K19) -> 0 | L9: =SUM('Game by Game Scores'!L17:L19) -> 0 | M9: =SUM('Game by Game Scores'!M17:M19) -> 0 | N9: =SUM('Game by Game Scores'!N17:N19) -> 0 | O9: =SUM('Game by Game Scores'!O17:O19) -> 0 | P9: =SUM('Game by Game Scores'!P17:P19) -> 0
A10: Week 6 | B10: =SUM('Game by Game Scores'!B20:B22) -> 0 | C10: =SUM('Game by Game Scores'!C20:C22) -> 0 | D10: =SUM('Game by Game Scores'!D20:D22) -> 0 | E10: =SUM('Game by Game Scores'!E20:E22) -> 0 | F10: =SUM('Game by Game Scores'!F20:F22) -> 0 | G10: =SUM('Game by Game Scores'!G20:G22) -> 0 | J10: Week 6 | K10: =SUM('Game by Game Scores'!K20:K22) -> 0 | L10: =SUM('Game by Game Scores'!L20:L22) -> 0 | M10: =SUM('Game by Game Scores'!M20:M22) -> 0 | N10: =SUM('Game by Game Scores'!N20:N22) -> 0 | O10: =SUM('Game by Game Scores'!O20:O22) -> 0 | P10: =SUM('Game by Game Scores'!P20:P22) -> 0
A11: Week 7 | B11: =SUM('Game by Game Scores'!B23:B25) -> 0 | C11: =SUM('Game by Game Scores'!C23:C25) -> 0 | D11: =SUM('Game by Game Scores'!D23:D25) -> 0 | E11: =SUM('Game by Game Scores'!E23:E25) -> 0 | F11: =SUM('Game by Game Scores'!F23:F25) -> 0 | G11: =SUM('Game by Game Scores'!G23:G25) -> 0 | J11: Week 7 | K11: =SUM('Game by Game Scores'!K23:K25) -> 0 | L11: =SUM('Game by Game Scores'!L23:L25) -> 0 | M11: =SUM('Game by Game Scores'!M23:M25) -> 0 | N11: =SUM('Game by Game Scores'!N23:N25) -> 0 | O11: =SUM('Game by Game Scores'!O23:O25) -> 0 | P11: =SUM('Game by Game Scores'!P23:P25) -> 0
A12: Week 8 | B12: =SUM('Game by Game Scores'!B26:B28) -> 0 | C12: =SUM('Game by Game Scores'!C26:C28) -> 0 | D12: =SUM('Game by Game Scores'!D26:D28) -> 0 | E12: =SUM('Game by Game Scores'!E26:E28) -> 0 | F12: =SUM('Game by Game Scores'!F26:F28) -> 0 | G12: =SUM('Game by Game Scores'!G26:G28) -> 0 | J12: Week 8 | K12: =SUM('Game by Game Scores'!K26:K28) -> 0 | L12: =SUM('Game by Game Scores'!L26:L28) -> 0 | M12: =SUM('Game by Game Scores'!M26:M28) -> 0 | N12: =SUM('Game by Game Scores'!N26:N28) -> 0 | O12: =SUM('Game by Game Scores'!O26:O28) -> 0 | P12: =SUM('Game by Game Scores'!P26:P28) -> 0
A13: Week 9 | B13: =SUM('Game by Game Scores'!B29:B31) -> 0 | C13: =SUM('Game by Game Scores'!C29:C31) -> 0 | D13: =SUM('Game by Game Scores'!D29:D31) -> 0 | E13: =SUM('Game by Game Scores'!E29:E31) -> 0 | F13: =SUM('Game by Game Scores'!F29:F31) -> 0 | G13: =SUM('Game by Game Scores'!G29:G31) -> 0 | J13: Week 9 | K13: =SUM('Game by Game Scores'!K29:K31) -> 0 | L13: =SUM('Game by Game Scores'!L29:L31) -> 0 | M13: =SUM('Game by Game Scores'!M29:M31) -> 0 | N13: =SUM('Game by Game Scores'!N29:N31) -> 0 | O13: =SUM('Game by Game Scores'!O29:O31) -> 0 | P13: =SUM('Game by Game Scores'!P29:P31) -> 0
A14: Week 10 | B14: =SUM('Game by Game Scores'!B32:B34) -> 0 | C14: =SUM('Game by Game Scores'!C32:C34) -> 0 | D14: =SUM('Game by Game Scores'!D32:D34) -> 0 | E14: =SUM('Game by Game Scores'!E32:E34) -> 0 | F14: =SUM('Game by Game Scores'!F32:F34) -> 0 | G14: =SUM('Game by Game Scores'!G32:G34) -> 0 | J14: Week 10 | K14: =SUM('Game by Game Scores'!K32:K34) -> 0 | L14: =SUM('Game by Game Scores'!L32:L34) -> 0 | M14: =SUM('Game by Game Scores'!M32:M34) -> 0 | N14: =SUM('Game by Game Scores'!N32:N34) -> 0 | O14: =SUM('Game by Game Scores'!O32:O34) -> 0 | P14: =SUM('Game by Game Scores'!P32:P34) -> 0
A15: Week 11 | B15: =SUM('Game by Game Scores'!B35:B37) -> 0 | C15: =SUM('Game by Game Scores'!C35:C37) -> 0 | D15: =SUM('Game by Game Scores'!D35:D37) -> 0 | E15: =SUM('Game by Game Scores'!E35:E37) -> 0 | F15: =SUM('Game by Game Scores'!F35:F37) -> 0 | G15: =SUM('Game by Game Scores'!G35:G37) -> 0 | J15: Week 11 | K15: =SUM('Game by Game Scores'!K35:K37) -> 0 | L15: =SUM('Game by Game Scores'!L35:L37) -> 0 | M15: =SUM('Game by Game Scores'!M35:M37) -> 0 | N15: =SUM('Game by Game Scores'!N35:N37) -> 0 | O15: =SUM('Game by Game Scores'!O35:O37) -> 0 | P15: =SUM('Game by Game Scores'!P35:P37) -> 0
A16: Week 12 | B16: =SUM('Game by Game Scores'!B38:B40) -> 0 | C16: =SUM('Game by Game Scores'!C38:C40) -> 0 | D16: =SUM('Game by Game Scores'!D38:D40) -> 0 | E16: =SUM('Game by Game Scores'!E38:E40) -> 0 | F16: =SUM('Game by Game Scores'!F38:F40) -> 0 | G16: =SUM('Game by Game Scores'!G38:G40) -> 0 | J16: Week 12 | K16: =SUM('Game by Game Scores'!K38:K40) -> 0 | L16: =SUM('Game by Game Scores'!L38:L40) -> 0 | M16: =SUM('Game by Game Scores'!M38:M40) -> 0 | N16: =SUM('Game by Game Scores'!N38:N40) -> 0 | O16: =SUM('Game by Game Scores'!O38:O40) -> 0 | P16: =SUM('Game by Game Scores'!P38:P40) -> 0
A17: Week 13 | B17: =SUM('Game by Game Scores'!B41:B43) -> 0 | C17: =SUM('Game by Game Scores'!C41:C43) -> 0 | D17: =SUM('Game by Game Scores'!D41:D43) -> 0 | E17: =SUM('Game by Game Scores'!E41:E43) -> 0 | F17: =SUM('Game by Game Scores'!F41:F43) -> 0 | G17: =SUM('Game by Game Scores'!G41:G43) -> 0 | J17: Week 13 | K17: =SUM('Game by Game Scores'!K41:K43) -> 0 | L17: =SUM('Game by Game Scores'!L41:L43) -> 0 | M17: =SUM('Game by Game Scores'!M41:M43) -> 0 | N17: =SUM('Game by Game Scores'!N41:N43) -> 0 | O17: =SUM('Game by Game Scores'!O41:O43) -> 0 | P17: =SUM('Game by Game Scores'!P41:P43) -> 0
A18: Week 14 | B18: =SUM('Game by Game Scores'!B44:B46) -> 0 | C18: =SUM('Game by Game Scores'!C44:C46) -> 0 | D18: =SUM('Game by Game Scores'!D44:D46) -> 0 | E18: =SUM('Game by Game Scores'!E44:E46) -> 0 | F18: =SUM('Game by Game Scores'!F44:F46) -> 0 | G18: =SUM('Game by Game Scores'!G44:G46) -> 0 | J18: Week 14 | K18: =SUM('Game by Game Scores'!K44:K46) -> 0 | L18: =SUM('Game by Game Scores'!L44:L46) -> 0 | M18: =SUM('Game by Game Scores'!M44:M46) -> 0 | N18: =SUM('Game by Game Scores'!N44:N46) -> 0 | O18: =SUM('Game by Game Scores'!O44:O46) -> 0 | P18: =SUM('Game by Game Scores'!P44:P46) -> 0
A19: Week 15 | B19: =SUM('Game by Game Scores'!B47:B49) -> 0 | C19: =SUM('Game by Game Scores'!C47:C49) -> 0 | D19: =SUM('Game by Game Scores'!D47:D49) -> 0 | E19: =SUM('Game by Game Scores'!E47:E49) -> 0 | F19: =SUM('Game by Game Scores'!F47:F49) -> 0 | G19: =SUM('Game by Game Scores'!G47:G49) -> 0 | J19: Week 15 | K19: =SUM('Game by Game Scores'!K47:K49) -> 0 | L19: =SUM('Game by Game Scores'!L47:L49) -> 0 | M19: =SUM('Game by Game Scores'!M47:M49) -> 0 | N19: =SUM('Game by Game Scores'!N47:N49) -> 0 | O19: =SUM('Game by Game Scores'!O47:O49) -> 0 | P19: =SUM('Game by Game Scores'!P47:P49) -> 0
A20: Week 16 | B20: =SUM('Game by Game Scores'!B50:B52) -> 0 | C20: =SUM('Game by Game Scores'!C50:C52) -> 0 | D20: =SUM('Game by Game Scores'!D50:D52) -> 0 | E20: =SUM('Game by Game Scores'!E50:E52) -> 0 | F20: =SUM('Game by Game Scores'!F50:F52) -> 0 | G20: =SUM('Game by Game Scores'!G50:G52) -> 0 | J20: Week 16 | K20: =SUM('Game by Game Scores'!K50:K52) -> 0 | L20: =SUM('Game by Game Scores'!L50:L52) -> 0 | M20: =SUM('Game by Game Scores'!M50:M52) -> 0 | N20: =SUM('Game by Game Scores'!N50:N52) -> 0 | O20: =SUM('Game by Game Scores'!O50:O52) -> 0 | P20: =SUM('Game by Game Scores'!P50:P52) -> 0
A21: Week 17 | B21: =SUM('Game by Game Scores'!B53:B55) -> 0 | C21: =SUM('Game by Game Scores'!C53:C55) -> 0 | D21: =SUM('Game by Game Scores'!D53:D55) -> 0 | E21: =SUM('Game by Game Scores'!E53:E55) -> 0 | F21: =SUM('Game by Game Scores'!F53:F55) -> 0 | G21: =SUM('Game by Game Scores'!G53:G55) -> 0 | J21: Week 17 | K21: =SUM('Game by Game Scores'!K53:K55) -> 0 | L21: =SUM('Game by Game Scores'!L53:L55) -> 0 | M21: =SUM('Game by Game Scores'!M53:M55) -> 0 | N21: =SUM('Game by Game Scores'!N53:N55) -> 0 | O21: =SUM('Game by Game Scores'!O53:O55) -> 0 | P21: =SUM('Game by Game Scores'!P53:P55) -> 0
A22: Week 18 | B22: =SUM('Game by Game Scores'!B56:B58) -> 0 | C22: =SUM('Game by Game Scores'!C56:C58) -> 0 | D22: =SUM('Game by Game Scores'!D56:D58) -> 0 | E22: =SUM('Game by Game Scores'!E56:E58) -> 0 | F22: =SUM('Game by Game Scores'!F56:F58) -> 0 | G22: =SUM('Game by Game Scores'!G56:G58) -> 0 | J22: Week 18 | K22: =SUM('Game by Game Scores'!K56:K58) -> 0 | L22: =SUM('Game by Game Scores'!L56:L58) -> 0 | M22: =SUM('Game by Game Scores'!M56:M58) -> 0 | N22: =SUM('Game by Game Scores'!N56:N58) -> 0 | O22: =SUM('Game by Game Scores'!O56:O58) -> 0 | P22: =SUM('Game by Game Scores'!P56:P58) -> 0
A23: Week 19 | B23: =SUM('Game by Game Scores'!B59:B61) -> 0 | C23: =SUM('Game by Game Scores'!C59:C61) -> 0 | D23: =SUM('Game by Game Scores'!D59:D61) -> 0 | E23: =SUM('Game by Game Scores'!E59:E61) -> 0 | F23: =SUM('Game by Game Scores'!F59:F61) -> 0 | G23: =SUM('Game by Game Scores'!G59:G61) -> 0 | J23: Week 19 | K23: =SUM('Game by Game Scores'!K59:K61) -> 0 | L23: =SUM('Game by Game Scores'!L59:L61) -> 0 | M23: =SUM('Game by Game Scores'!M59:M61) -> 0 | N23: =SUM('Game by Game Scores'!N59:N61) -> 0 | O23: =SUM('Game by Game Scores'!O59:O61) -> 0 | P23: =SUM('Game by Game Scores'!P59:P61) -> 0
A24: Week 20 | B24: =SUM('Game by Game Scores'!B62:B64) -> 0 | C24: =SUM('Game by Game Scores'!C62:C64) -> 0 | D24: =SUM('Game by Game Scores'!D62:D64) -> 0 | E24: =SUM('Game by Game Scores'!E62:E64) -> 0 | F24: =SUM('Game by Game Scores'!F62:F64) -> 0 | G24: =SUM('Game by Game Scores'!G62:G64) -> 0 | J24: Week 20 | K24: =SUM('Game by Game Scores'!K62:K64) -> 0 | L24: =SUM('Game by Game Scores'!L62:L64) -> 0 | M24: =SUM('Game by Game Scores'!M62:M64) -> 0 | N24: =SUM('Game by Game Scores'!N62:N64) -> 0 | O24: =SUM('Game by Game Scores'!O62:O64) -> 0 | P24: =SUM('Game by Game Scores'!P62:P64) -> 0
A25: Week 21 | B25: =SUM('Game by Game Scores'!B65:B67) -> 0 | C25: =SUM('Game by Game Scores'!C65:C67) -> 0 | D25: =SUM('Game by Game Scores'!D65:D67) -> 0 | E25: =SUM('Game by Game Scores'!E65:E67) -> 0 | F25: =SUM('Game by Game Scores'!F65:F67) -> 0 | G25: =SUM('Game by Game Scores'!G65:G67) -> 0 | J25: Week 21 | K25: =SUM('Game by Game Scores'!K65:K67) -> 0 | L25: =SUM('Game by Game Scores'!L65:L67) -> 0 | M25: =SUM('Game by Game Scores'!M65:M67) -> 0 | N25: =SUM('Game by Game Scores'!N65:N67) -> 0 | O25: =SUM('Game by Game Scores'!O65:O67) -> 0 | P25: =SUM('Game by Game Scores'!P65:P67) -> 0
A26: Week 22 | B26: =SUM('Game by Game Scores'!B68:B70) -> 0 | C26: =SUM('Game by Game Scores'!C68:C70) -> 0 | D26: =SUM('Game by Game Scores'!D68:D70) -> 0 | E26: =SUM('Game by Game Scores'!E68:E70) -> 0 | F26: =SUM('Game by Game Scores'!F68:F70) -> 0 | G26: =SUM('Game by Game Scores'!G68:G70) -> 0 | J26: Week 22 | K26: =SUM('Game by Game Scores'!K68:K70) -> 0 | L26: =SUM('Game by Game Scores'!L68:L70) -> 0 | M26: =SUM('Game by Game Scores'!M68:M70) -> 0 | N26: =SUM('Game by Game Scores'!N68:N70) -> 0 | O26: =SUM('Game by Game Scores'!O68:O70) -> 0 | P26: =SUM('Game by Game Scores'!P68:P70) -> 0
A27: Week 23 | B27: =SUM('Game by Game Scores'!B71:B73) -> 0 | C27: =SUM('Game by Game Scores'!C71:C73) -> 0 | D27: =SUM('Game by Game Scores'!D71:D73) -> 0 | E27: =SUM('Game by Game Scores'!E71:E73) -> 0 | F27: =SUM('Game by Game Scores'!F71:F73) -> 0 | G27: =SUM('Game by Game Scores'!G71:G73) -> 0 | J27: Week 23 | K27: =SUM('Game by Game Scores'!K71:K73) -> 0 | L27: =SUM('Game by Game Scores'!L71:L73) -> 0 | M27: =SUM('Game by Game Scores'!M71:M73) -> 0 | N27: =SUM('Game by Game Scores'!N71:N73) -> 0 | O27: =SUM('Game by Game Scores'!O71:O73) -> 0 | P27: =SUM('Game by Game Scores'!P71:P73) -> 0
A28: Week 24 | B28: =SUM('Game by Game Scores'!B74:B76) -> 0 | C28: =SUM('Game by Game Scores'!C74:C76) -> 0 | D28: =SUM('Game by Game Scores'!D74:D76) -> 0 | E28: =SUM('Game by Game Scores'!E74:E76) -> 0 | F28: =SUM('Game by Game Scores'!F74:F76) -> 0 | G28: =SUM('Game by Game Scores'!G74:G76) -> 0 | J28: Week 24 | K28: =SUM('Game by Game Scores'!K74:K76) -> 0 | L28: =SUM('Game by Game Scores'!L74:L76) -> 0 | M28: =SUM('Game by Game Scores'!M74:M76) -> 0 | N28: =SUM('Game by Game Scores'!N74:N76) -> 0 | O28: =SUM('Game by Game Scores'!O74:O76) -> 0 | P28: =SUM('Game by Game Scores'!P74:P76) -> 0
A29: Week 25 | B29: =SUM('Game by Game Scores'!B77:B79) -> 0 | C29: =SUM('Game by Game Scores'!C77:C79) -> 0 | D29: =SUM('Game by Game Scores'!D77:D79) -> 0 | E29: =SUM('Game by Game Scores'!E77:E79) -> 0 | F29: =SUM('Game by Game Scores'!F77:F79) -> 0 | G29: =SUM('Game by Game Scores'!G77:G79) -> 0 | J29: Week 25 | K29: =SUM('Game by Game Scores'!K77:K79) -> 0 | L29: =SUM('Game by Game Scores'!L77:L79) -> 0 | M29: =SUM('Game by Game Scores'!M77:M79) -> 0 | N29: =SUM('Game by Game Scores'!N77:N79) -> 0 | O29: =SUM('Game by Game Scores'!O77:O79) -> 0 | P29: =SUM('Game by Game Scores'!P77:P79) -> 0
A30: Week 26 | B30: =SUM('Game by Game Scores'!B80:B82) -> 0 | C30: =SUM('Game by Game Scores'!C80:C82) -> 0 | D30: =SUM('Game by Game Scores'!D80:D82) -> 0 | E30: =SUM('Game by Game Scores'!E80:E82) -> 0 | F30: =SUM('Game by Game Scores'!F80:F82) -> 0 | G30: =SUM('Game by Game Scores'!G80:G82) -> 0 | J30: Week 26 | K30: =SUM('Game by Game Scores'!K80:K82) -> 0 | L30: =SUM('Game by Game Scores'!L80:L82) -> 0 | M30: =SUM('Game by Game Scores'!M80:M82) -> 0 | N30: =SUM('Game by Game Scores'!N80:N82) -> 0 | O30: =SUM('Game by Game Scores'!O80:O82) -> 0 | P30: =SUM('Game by Game Scores'!P80:P82) -> 0
A31: Week 27 | B31: =SUM('Game by Game Scores'!B83:B85) -> 0 | C31: =SUM('Game by Game Scores'!C83:C85) -> 0 | D31: =SUM('Game by Game Scores'!D83:D85) -> 0 | E31: =SUM('Game by Game Scores'!E83:E85) -> 0 | F31: =SUM('Game by Game Scores'!F83:F85) -> 0 | G31: =SUM('Game by Game Scores'!G83:G85) -> 0 | J31: Week 27 | K31: =SUM('Game by Game Scores'!K83:K85) -> 0 | L31: =SUM('Game by Game Scores'!L83:L85) -> 0 | M31: =SUM('Game by Game Scores'!M83:M85) -> 0 | N31: =SUM('Game by Game Scores'!N83:N85) -> 0 | O31: =SUM('Game by Game Scores'!O83:O85) -> 0 | P31: =SUM('Game by Game Scores'!P83:P85) -> 0
A32: Week 28 | B32: =SUM('Game by Game Scores'!B86:B88) -> 0 | C32: =SUM('Game by Game Scores'!C86:C88) -> 0 | D32: =SUM('Game by Game Scores'!D86:D88) -> 0 | E32: =SUM('Game by Game Scores'!E86:E88) -> 0 | F32: =SUM('Game by Game Scores'!F86:F88) -> 0 | G32: =SUM('Game by Game Scores'!G86:G88) -> 0 | J32: Week 28 | K32: =SUM('Game by Game Scores'!K86:K88) -> 0 | L32: =SUM('Game by Game Scores'!L86:L88) -> 0 | M32: =SUM('Game by Game Scores'!M86:M88) -> 0 | N32: =SUM('Game by Game Scores'!N86:N88) -> 0 | O32: =SUM('Game by Game Scores'!O86:O88) -> 0 | P32: =SUM('Game by Game Scores'!P86:P88) -> 0
A33: Week 29 | B33: =SUM('Game by Game Scores'!B89:B91) -> 0 | C33: =SUM('Game by Game Scores'!C89:C91) -> 0 | D33: =SUM('Game by Game Scores'!D89:D91) -> 0 | E33: =SUM('Game by Game Scores'!E89:E91) -> 0 | F33: =SUM('Game by Game Scores'!F89:F91) -> 0 | G33: =SUM('Game by Game Scores'!G89:G91) -> 0 | J33: Week 29 | K33: =SUM('Game by Game Scores'!K89:K91) -> 0 | L33: =SUM('Game by Game Scores'!L89:L91) -> 0 | M33: =SUM('Game by Game Scores'!M89:M91) -> 0 | N33: =SUM('Game by Game Scores'!N89:N91) -> 0 | O33: =SUM('Game by Game Scores'!O89:O91) -> 0 | P33: =SUM('Game by Game Scores'!P89:P91) -> 0
A34: Week 30 | B34: =SUM('Game by Game Scores'!B92:B94) -> 0 | C34: =SUM('Game by Game Scores'!C92:C94) -> 0 | D34: =SUM('Game by Game Scores'!D92:D94) -> 0 | E34: =SUM('Game by Game Scores'!E92:E94) -> 0 | F34: =SUM('Game by Game Scores'!F92:F94) -> 0 | G34: =SUM('Game by Game Scores'!G92:G94) -> 0 | J34: Week 30 | K34: =SUM('Game by Game Scores'!K92:K94) -> 0 | L34: =SUM('Game by Game Scores'!L92:L94) -> 0 | M34: =SUM('Game by Game Scores'!M92:M94) -> 0 | N34: =SUM('Game by Game Scores'!N92:N94) -> 0 | O34: =SUM('Game by Game Scores'!O92:O94) -> 0 | P34: =SUM('Game by Game Scores'!P92:P94) -> 0
A35: Week 31 | B35: =SUM('Game by Game Scores'!B95:B97) -> 0 | C35: =SUM('Game by Game Scores'!C95:C97) -> 0 | D35: =SUM('Game by Game Scores'!D95:D97) -> 0 | E35: =SUM('Game by Game Scores'!E95:E97) -> 0 | F35: =SUM('Game by Game Scores'!F95:F97) -> 0 | G35: =SUM('Game by Game Scores'!G95:G97) -> 0 | J35: Week 31 | K35: =SUM('Game by Game Scores'!K95:K97) -> 0 | L35: =SUM('Game by Game Scores'!L95:L97) -> 0 | M35: =SUM('Game by Game Scores'!M95:M97) -> 0 | N35: =SUM('Game by Game Scores'!N95:N97) -> 0 | O35: =SUM('Game by Game Scores'!O95:O97) -> 0 | P35: =SUM('Game by Game Scores'!P95:P97) -> 0
A36: Week 32 | B36: =SUM('Game by Game Scores'!B98:B100) -> 0 | C36: =SUM('Game by Game Scores'!C98:C100) -> 0 | D36: =SUM('Game by Game Scores'!D98:D100) -> 0 | E36: =SUM('Game by Game Scores'!E98:E100) -> 0 | F36: =SUM('Game by Game Scores'!F98:F100) -> 0 | G36: =SUM('Game by Game Scores'!G98:G100) -> 0 | J36: Week 32 | K36: =SUM('Game by Game Scores'!K98:K100) -> 0 | L36: =SUM('Game by Game Scores'!L98:L100) -> 0 | M36: =SUM('Game by Game Scores'!M98:M100) -> 0 | N36: =SUM('Game by Game Scores'!N98:N100) -> 0 | O36: =SUM('Game by Game Scores'!O98:O100) -> 0 | P36: =SUM('Game by Game Scores'!P98:P100) -> 0
A37: Week 33 | B37: =SUM('Game by Game Scores'!B101:B103) -> 0 | C37: =SUM('Game by Game Scores'!C101:C103) -> 0 | D37: =SUM('Game by Game Scores'!D101:D103) -> 0 | E37: =SUM('Game by Game Scores'!E101:E103) -> 0 | F37: =SUM('Game by Game Scores'!F101:F103) -> 0 | G37: =SUM('Game by Game Scores'!G101:G103) -> 0 | J37: Week 33 | K37: =SUM('Game by Game Scores'!K101:K103) -> 0 | L37: =SUM('Game by Game Scores'!L101:L103) -> 0 | M37: =SUM('Game by Game Scores'!M101:M103) -> 0 | N37: =SUM('Game by Game Scores'!N101:N103) -> 0 | O37: =SUM('Game by Game Scores'!O101:O103) -> 0 | P37: =SUM('Game by Game Scores'!P101:P103) -> 0
A38: Week 34 | B38: =SUM('Game by Game Scores'!B104:B106) -> 0 | C38: =SUM('Game by Game Scores'!C104:C106) -> 0 | D38: =SUM('Game by Game Scores'!D104:D106) -> 0 | E38: =SUM('Game by Game Scores'!E104:E106) -> 0 | F38: =SUM('Game by Game Scores'!F104:F106) -> 0 | G38: =SUM('Game by Game Scores'!G104:G106) -> 0 | J38: Week 34 | K38: =SUM('Game by Game Scores'!K104:K106) -> 0 | L38: =SUM('Game by Game Scores'!L104:L106) -> 0 | M38: =SUM('Game by Game Scores'!M104:M106) -> 0 | N38: =SUM('Game by Game Scores'!N104:N106) -> 0 | O38: =SUM('Game by Game Scores'!O104:O106) -> 0 | P38: =SUM('Game by Game Scores'!P104:P106) -> 0
A39: Week 35 | B39: =SUM('Game by Game Scores'!B107:B109) -> 0 | C39: =SUM('Game by Game Scores'!C107:C109) -> 0 | D39: =SUM('Game by Game Scores'!D107:D109) -> 0 | E39: =SUM('Game by Game Scores'!E107:E109) -> 0 | F39: =SUM('Game by Game Scores'!F107:F109) -> 0 | G39: =SUM('Game by Game Scores'!G107:G109) -> 0 | J39: Week 35 | K39: =SUM('Game by Game Scores'!K107:K109) -> 0 | L39: =SUM('Game by Game Scores'!L107:L109) -> 0 | M39: =SUM('Game by Game Scores'!M107:M109) -> 0 | N39: =SUM('Game by Game Scores'!N107:N109) -> 0 | O39: =SUM('Game by Game Scores'!O107:O109) -> 0 | P39: =SUM('Game by Game Scores'!P107:P109) -> 0
A40: Week 36 | B40: =SUM('Game by Game Scores'!B110:B112) -> 0 | C40: =SUM('Game by Game Scores'!C110:C112) -> 0 | D40: =SUM('Game by Game Scores'!D110:D112) -> 0 | E40: =SUM('Game by Game Scores'!E110:E112) -> 0 | F40: =SUM('Game by Game Scores'!F110:F112) -> 0 | G40: =SUM('Game by Game Scores'!G110:G112) -> 0 | J40: Week 36 | K40: =SUM('Game by Game Scores'!K110:K112) -> 0 | L40: =SUM('Game by Game Scores'!L110:L112) -> 0 | M40: =SUM('Game by Game Scores'!M110:M112) -> 0 | N40: =SUM('Game by Game Scores'!N110:N112) -> 0 | O40: =SUM('Game by Game Scores'!O110:O112) -> 0 | P40: =SUM('Game by Game Scores'!P110:P112) -> 0

Sheet Opponent Week by Week Scores
C2: Without Handicap | L2: With Handicap
B4: John | C4: Nick | D4: Mike | E4: Eric | F4: Greenman | G4: Ron | K4: John | L4: Nick | M4: Mike | N4: Eric | O4: Greenman | P4: Ron
A5: Week 1 | B5: =SUM('Opponent Game by Game Scores'!B5:B7) -> 664 | C5: =SUM('Opponent Game by Game Scores'!C5:C7) -> 543 | D5: =SUM('Opponent Game by Game Scores'!D5:D7) -> 601 | E5: =SUM('Opponent Game by Game Scores'!E5:E7) -> 641 | F5: =SUM('Opponent Game by Game Scores'!F5:F7) -> 622 | H5: =SUM('Opponent Game by Game Scores'!H5:H7) -> 0 | I5: =SUM('Opponent Game by Game Scores'!I5:I7) -> 0 | J5: Week 1 | K5: =SUM('Opponent Game by Game Scores'!K5:K7) -> 664 | L5: =SUM('Opponent Game by Game Scores'!L5:L7) -> 546 | M5: =SUM('Opponent Game by Game Scores'!M5:M7) -> 601 | N5: =SUM('Opponent Game by Game Scores'!N5:N7) -> 653 | O5: =SUM('Opponent Game by Game Scores'!O5:O7) -> 622
A6: Week 2 | B6: =SUM('Opponent Game by Game Scores'!B8:B10) -> 642 | C6: =SUM('Opponent Game by Game Scores'!C8:C10) -> 659 | D6: =SUM('Opponent Game by Game Scores'!D8:D10) -> 621 | E6: =SUM('Opponent Game by Game Scores'!E8:E10) -> 645 | F6: =SUM('Opponent Game by Game Scores'!F8:F10) -> 492 | J6: Week 2 | K6: =SUM('Opponent Game by Game Scores'!K8:K10) -> 642 | L6: =SUM('Opponent Game by Game Scores'!L8:L10) -> 674 | M6: =SUM('Opponent Game by Game Scores'!M8:M10) -> 621 | N6: =SUM('Opponent Game by Game Scores'!N8:N10) -> 645 | O6: =SUM('Opponent Game by Game Scores'!O8:O10) -> 492
A7: Week 3 | C7: =SUM('Opponent Game by Game Scores'!C11:C13) -> 707 | D7: =SUM('Opponent Game by Game Scores'!D11:D13) -> 555 | E7: =SUM('Opponent Game by Game Scores'!E11:E13) -> 555 | G7: =SUM('Opponent Game by Game Scores'!G11:G13) -> 514 | J7: Week 3 | L7: =SUM('Opponent Game by Game Scores'!L11:L13) -> 707 | M7: =SUM('Opponent Game by Game Scores'!M11:M13) -> 561 | N7: =SUM('Opponent Game by Game Scores'!N11:N13) -> 558 | P7: =SUM('Opponent Game by Game Scores'!P11:P13) -> 586
A8: Week 4 | B8: =SUM('Opponent Game by Game Scores'!B14:B16) -> 0 | C8: =SUM('Opponent Game by Game Scores'!C14:C16) -> 0 | D8: =SUM('Opponent Game by Game Scores'!D14:D16) -> 0 | E8: =SUM('Opponent Game by Game Scores'!E14:E16) -> 0 | F8: =SUM('Opponent Game by Game Scores'!F14:F16) -> 0 | G8: =SUM('Opponent Game by Game Scores'!G14:G16) -> 0 | J8: Week 4 | K8: =SUM('Opponent Game by Game Scores'!K14:K16) -> 0 | L8: =SUM('Opponent Game by Game Scores'!L14:L16) -> 0 | M8: =SUM('Opponent Game by Game Scores'!M14:M16) -> 0 | N8: =SUM('Opponent Game by Game Scores'!N14:N16) -> 0 | O8: =SUM('Opponent Game by Game Scores'!O14:O16) -> 0 | P8: =SUM('Opponent Game by Game Scores'!P14:P16) -> 0
A9: Week 5 | B9: =SUM('Opponent Game by Game Scores'!B17:B19) -> 0 | C9: =SUM('Opponent Game by Game Scores'!C17:C19) -> 0 | D9: =SUM('Opponent Game by Game Scores'!D17:D19) -> 0 | E9: =SUM('Opponent Game by Game Scores'!E17:E19) -> 0 | F9: =SUM('Opponent Game by Game Scores'!F17:F19) -> 0 | G9: =SUM('Opponent Game by Game Scores'!G17:G19) -> 0 | J9: Week 5 | K9: =SUM('Opponent Game by Game Scores'!K17:K19) -> 0 | L9: =SUM('Opponent Game by Game Scores'!L17:L19) -> 0 | M9: =SUM('Opponent Game by Game Scores'!M17:M19) -> 0 | N9: =SUM('Opponent Game by Game Scores'!N17:N19) -> 0 | O9: =SUM('Opponent Game by Game Scores'!O17:O19) -> 0 | P9: =SUM('Opponent Game by Game Scores'!P17:P19) -> 0
A10: Week 6 | B10: =SUM('Opponent Game by Game Scores'!B20:B22) -> 0 | C10: =SUM('Opponent Game by Game Scores'!C20:C22) -> 0 | D10: =SUM('Opponent Game by Game Scores'!D20:D22) -> 0 | E10: =SUM('Opponent Game by Game Scores'!E20:E22) -> 0 | F10: =SUM('Opponent Game by Game Scores'!F20:F22) -> 0 | G10: =SUM('Opponent Game by Game Scores'!G20:G22) -> 0 | J10: Week 6 | K10: =SUM('Opponent Game by Game Scores'!K20:K22) -> 0 | L10: =SUM('Opponent Game by Game Scores'!L20:L22) -> 0 | M10: =SUM('Opponent Game by Game Scores'!M20:M22) -> 0 | N10: =SUM('Opponent Game by Game Scores'!N20:N22) -> 0 | O10: =SUM('Opponent Game by Game Scores'!O20:O22) -> 0 | P10: =SUM('Opponent Game by Game Scores'!P20:P22) -> 0
A11: Week 7 | B11: =SUM('Opponent Game by Game Scores'!B23:B25) -> 0 | C11: =SUM('Opponent Game by Game Scores'!C23:C25) -> 0 | D11: =SUM('Opponent Game by Game Scores'!D23:D25) -> 0 | E11: =SUM('Opponent Game by Game Scores'!E23:E25) -> 0 | F11: =SUM('Opponent Game by Game Scores'!F23:F25) -> 0 | G11: =SUM('Opponent Game by Game Scores'!G23:G25) -> 0 | J11: Week 7 | K11: =SUM('Opponent Game by Game Scores'!K23:K25) -> 0 | L11: =SUM('Opponent Game by Game Scores'!L23:L25) -> 0 | M11: =SUM('Opponent Game by Game Scores'!M23:M25) -> 0 | N11: =SUM('Opponent Game by Game Scores'!N23:N25) -> 0 | O11: =SUM('Opponent Game by Game Scores'!O23:O25) -> 0 | P11: =SUM('Opponent Game by Game Scores'!P23:P25) -> 0
A12: Week 8 | B12: =SUM('Opponent Game by Game Scores'!B26:B28) -> 0 | C12: =SUM('Opponent Game by Game Scores'!C26:C28) -> 0 | D12: =SUM('Opponent Game by Game Scores'!D26:D28) -> 0 | E12: =SUM('Opponent Game by Game Scores'!E26:E28) -> 0 | F12: =SUM('Opponent Game by Game Scores'!F26:F28) -> 0 | G12: =SUM('Opponent Game by Game Scores'!G26:G28) -> 0 | J12: Week 8 | K12: =SUM('Opponent Game by Game Scores'!K26:K28) -> 0 | L12: =SUM('Opponent Game by Game Scores'!L26:L28) -> 0 | M12: =SUM('Opponent Game by Game Scores'!M26:M28) -> 0 | N12: =SUM('Opponent Game by Game Scores'!N26:N28) -> 0 | O12: =SUM('Opponent Game by Game Scores'!O26:O28) -> 0 | P12: =SUM('Opponent Game by Game Scores'!P26:P28) -> 0
A13: Week 9 | B13: =SUM('Opponent Game by Game Scores'!B29:B31) -> 0 | C13: =SUM('Opponent Game by Game Scores'!C29:C31) -> 0 | D13: =SUM('Opponent Game by Game Scores'!D29:D31) -> 0 | E13: =SUM('Opponent Game by Game Scores'!E29:E31) -> 0 | F13: =SUM('Opponent Game by Game Scores'!F29:F31) -> 0 | G13: =SUM('Opponent Game by Game Scores'!G29:G31) -> 0 | J13: Week 9 | K13: =SUM('Opponent Game by Game Scores'!K29:K31) -> 0 | L13: =SUM('Opponent Game by Game Scores'!L29:L31) -> 0 | M13: =SUM('Opponent Game by Game Scores'!M29:M31) -> 0 | N13: =SUM('Opponent Game by Game Scores'!N29:N31) -> 0 | O13: =SUM('Opponent Game by Game Scores'!O29:O31) -> 0 | P13: =SUM('Opponent Game by Game Scores'!P29:P31) -> 0
A14: Week 10 | B14: =SUM('Opponent Game by Game Scores'!B32:B34) -> 0 | C14: =SUM('Opponent Game by Game Scores'!C32:C34) -> 0 | D14: =SUM('Opponent Game by Game Scores'!D32:D34) -> 0 | E14: =SUM('Opponent Game by Game Scores'!E32:E34) -> 0 | F14: =SUM('Opponent Game by Game Scores'!F32:F34) -> 0 | G14: =SUM('Opponent Game by Game Scores'!G32:G34) -> 0 | J14: Week 10 | K14: =SUM('Opponent Game by Game Scores'!K32:K34) -> 0 | L14: =SUM('Opponent Game by Game Scores'!L32:L34) -> 0 | M14: =SUM('Opponent Game by Game Scores'!M32:M34) -> 0 | N14: =SUM('Opponent Game by Game Scores'!N32:N34) -> 0 | O14: =SUM('Opponent Game by Game Scores'!O32:O34) -> 0 | P14: =SUM('Opponent Game by Game Scores'!P32:P34) -> 0
A15: Week 11 | B15: =SUM('Opponent Game by Game Scores'!B35:B37) -> 0 | C15: =SUM('Opponent Game by Game Scores'!C35:C37) -> 0 | D15: =SUM('Opponent Game by Game Scores'!D35:D37) -> 0 | E15: =SUM('Opponent Game by Game Scores'!E35:E37) -> 0 | F15: =SUM('Opponent Game by Game Scores'!F35:F37) -> 0 | G15: =SUM('Opponent Game by Game Scores'!G35:G37) -> 0 | J15: Week 11 | K15: =SUM('Opponent Game by Game Scores'!K35:K37) -> 0 | L15: =SUM('Opponent Game by Game Scores'!L35:L37) -> 0 | M15: =SUM('Opponent Game by Game Scores'!M35:M37) -> 0 | N15: =SUM('Opponent Game by Game Scores'!N35:N37) -> 0 | O15: =SUM('Opponent Game by Game Scores'!O35:O37) -> 0 | P15: =SUM('Opponent Game by Game Scores'!P35:P37) -> 0
A16: Week 12 | B16: =SUM('Opponent Game by Game Scores'!B38:B40) -> 0 | C16: =SUM('Opponent Game by Game Scores'!C38:C40) -> 0 | D16: =SUM('Opponent Game by Game Scores'!D38:D40) -> 0 | E16: =SUM('Opponent Game by Game Scores'!E38:E40) -> 0 | F16: =SUM('Opponent Game by Game Scores'!F38:F40) -> 0 | G16: =SUM('Opponent Game by Game Scores'!G38:G40) -> 0 | J16: Week 12 | K16: =SUM('Opponent Game by Game Scores'!K38:K40) -> 0 | L16: =SUM('Opponent Game by Game Scores'!L38:L40) -> 0 | M16: =SUM('Opponent Game by Game Scores'!M38:M40) -> 0 | N16: =SUM('Opponent Game by Game Scores'!N38:N40) -> 0 | O16: =SUM('Opponent Game by Game Scores'!O38:O40) -> 0 | P16: =SUM('Opponent Game by Game Scores'!P38:P40) -> 0
A17: Week 13 | B17: =SUM('Opponent Game by Game Scores'!B41:B43) -> 0 | C17: =SUM('Opponent Game by Game Scores'!C41:C43) -> 0 | D17: =SUM('Opponent Game by Game Scores'!D41:D43) -> 0 | E17: =SUM('Opponent Game by Game Scores'!E41:E43) -> 0 | F17: =SUM('Opponent Game by Game Scores'!F41:F43) -> 0 | G17: =SUM('Opponent Game by Game Scores'!G41:G43) -> 0 | J17: Week 13 | K17: =SUM('Opponent Game by Game Scores'!K41:K43) -> 0 | L17: =SUM('Opponent Game by Game Scores'!L41:L43) -> 0 | M17: =SUM('Opponent Game by Game Scores'!M41:M43) -> 0 | N17: =SUM('Opponent Game by Game Scores'!N41:N43) -> 0 | O17: =SUM('Opponent Game by Game Scores'!O41:O43) -> 0 | P17: =SUM('Opponent Game by Game Scores'!P41:P43) -> 0
A18: Week 14 | B18: =SUM('Opponent Game by Game Scores'!B44:B46) -> 0 | C18: =SUM('Opponent Game by Game Scores'!C44:C46) -> 0 | D18: =SUM('Opponent Game by Game Scores'!D44:D46) -> 0 | E18: =SUM('Opponent Game by Game Scores'!E44:E46) -> 0 | F18: =SUM('Opponent Game by Game Scores'!F44:F46) -> 0 | G18: =SUM('Opponent Game by Game Scores'!G44:G46) -> 0 | J18: Week 14 | K18: =SUM('Opponent Game by Game Scores'!K44:K46) -> 0 | L18: =SUM('Opponent Game by Game Scores'!L44:L46) -> 0 | M18: =SUM('Opponent Game by Game Scores'!M44:M46) -> 0 | N18: =SUM('Opponent Game by Game Scores'!N44:N46) -> 0 | O18: =SUM('Opponent Game by Game Scores'!O44:O46) -> 0 | P18: =SUM('Opponent Game by Game Scores'!P44:P46) -> 0
A19: Week 15 | B19: =SUM('Opponent Game by Game Scores'!B47:B49) -> 0 | C19: =SUM('Opponent Game by Game Scores'!C47:C49) -> 0 | D19: =SUM('Opponent Game by Game Scores'!D47:D49) -> 0 | E19: =SUM('Opponent Game by Game Scores'!E47:E49) -> 0 | F19: =SUM('Opponent Game by Game Scores'!F47:F49) -> 0 | G19: =SUM('Opponent Game by Game Scores'!G47:G49) -> 0 | J19: Week 15 | K19: =SUM('Opponent Game by Game Scores'!K47:K49) -> 0 | L19: =SUM('Opponent Game by Game Scores'!L47:L49) -> 0 | M19: =SUM('Opponent Game by Game Scores'!M47:M49) -> 0 | N19: =SUM('Opponent Game by Game Scores'!N47:N49) -> 0 | O19: =SUM('Opponent Game by Game Scores'!O47:O49) -> 0 | P19: =SUM('Opponent Game by Game Scores'!P47:P49) -> 0
A20: Week 16 | B20: =SUM('Opponent Game by Game Scores'!B50:B52) -> 0 | C20: =SUM('Opponent Game by Game Scores'!C50:C52) -> 0 | D20: =SUM('Opponent Game by Game Scores'!D50:D52) -> 0 | E20: =SUM('Opponent Game by Game Scores'!E50:E52) -> 0 | F20: =SUM('Opponent Game by Game Scores'!F50:F52) -> 0 | G20: =SUM('Opponent Game by Game Scores'!G50:G52) -> 0 | J20: Week 16 | K20: =SUM('Opponent Game by Game Scores'!K50:K52) -> 0 | L20: =SUM('Opponent Game by Game Scores'!L50:L52) -> 0 | M20: =SUM('Opponent Game by Game Scores'!M50:M52) -> 0 | N20: =SUM('Opponent Game by Game Scores'!N50:N52) -> 0 | O20: =SUM('Opponent Game by Game Scores'!O50:O52) -> 0 | P20: =SUM('Opponent Game by Game Scores'!P50:P52) -> 0
A21: Week 17 | B21: =SUM('Opponent Game by Game Scores'!B53:B55) -> 0 | C21: =SUM('Opponent Game by Game Scores'!C53:C55) -> 0 | D21: =SUM('Opponent Game by Game Scores'!D53:D55) -> 0 | E21: =SUM('Opponent Game by Game Scores'!E53:E55) -> 0 | F21: =SUM('Opponent Game by Game Scores'!F53:F55) -> 0 | G21: =SUM('Opponent Game by Game Scores'!G53:G55) -> 0 | J21: Week 17 | K21: =SUM('Opponent Game by Game Scores'!K53:K55) -> 0 | L21: =SUM('Opponent Game by Game Scores'!L53:L55) -> 0 | M21: =SUM('Opponent Game by Game Scores'!M53:M55) -> 0 | N21: =SUM('Opponent Game by Game Scores'!N53:N55) -> 0 | O21: =SUM('Opponent Game by Game Scores'!O53:O55) -> 0 | P21: =SUM('Opponent Game by Game Scores'!P53:P55) -> 0
A22: Week 18 | B22: =SUM('Opponent Game by Game Scores'!B56:B58) -> 0 | C22: =SUM('Opponent Game by Game Scores'!C56:C58) -> 0 | D22: =SUM('Opponent Game by Game Scores'!D56:D58) -> 0 | E22: =SUM('Opponent Game by Game Scores'!E56:E58) -> 0 | F22: =SUM('Opponent Game by Game Scores'!F56:F58) -> 0 | G22: =SUM('Opponent Game by Game Scores'!G56:G58) -> 0 | J22: Week 18 | K22: =SUM('Opponent Game by Game Scores'!K56:K58) -> 0 | L22: =SUM('Opponent Game by Game Scores'!L56:L58) -> 0 | M22: =SUM('Opponent Game by Game Scores'!M56:M58) -> 0 | N22: =SUM('Opponent Game by Game Scores'!N56:N58) -> 0 | O22: =SUM('Opponent Game by Game Scores'!O56:O58) -> 0 | P22: =SUM('Opponent Game by Game Scores'!P56:P58) -> 0
A23: Week 19 | B23: =SUM('Opponent Game by Game Scores'!B59:B61) -> 0 | C23: =SUM('Opponent Game by Game Scores'!C59:C61) -> 0 | D23: =SUM('Opponent Game by Game Scores'!D59:D61) -> 0 | E23: =SUM('Opponent Game by Game Scores'!E59:E61) -> 0 | F23: =SUM('Opponent Game by Game Scores'!F59:F61) -> 0 | G23: =SUM('Opponent Game by Game Scores'!G59:G61) -> 0 | J23: Week 19 | K23: =SUM('Opponent Game by Game Scores'!K59:K61) -> 0 | L23: =SUM('Opponent Game by Game Scores'!L59:L61) -> 0 | M23: =SUM('Opponent Game by Game Scores'!M59:M61) -> 0 | N23: =SUM('Opponent Game by Game Scores'!N59:N61) -> 0 | O23: =SUM('Opponent Game by Game Scores'!O59:O61) -> 0 | P23: =SUM('Opponent Game by Game Scores'!P59:P61) -> 0
A24: Week 20 | B24: =SUM('Opponent Game by Game Scores'!B62:B64) -> 0 | C24: =SUM('Opponent Game by Game Scores'!C62:C64) -> 0 | D24: =SUM('Opponent Game by Game Scores'!D62:D64) -> 0 | E24: =SUM('Opponent Game by Game Scores'!E62:E64) -> 0 | F24: =SUM('Opponent Game by Game Scores'!F62:F64) -> 0 | G24: =SUM('Opponent Game by Game Scores'!G62:G64) -> 0 | J24: Week 20 | K24: =SUM('Opponent Game by Game Scores'!K62:K64) -> 0 | L24: =SUM('Opponent Game by Game Scores'!L62:L64) -> 0 | M24: =SUM('Opponent Game by Game Scores'!M62:M64) -> 0 | N24: =SUM('Opponent Game by Game Scores'!N62:N64) -> 0 | O24: =SUM('Opponent Game by Game Scores'!O62:O64) -> 0 | P24: =SUM('Opponent Game by Game Scores'!P62:P64) -> 0
A25: Week 21 | B25: =SUM('Opponent Game by Game Scores'!B65:B67) -> 0 | C25: =SUM('Opponent Game by Game Scores'!C65:C67) -> 0 | D25: =SUM('Opponent Game by Game Scores'!D65:D67) -> 0 | E25: =SUM('Opponent Game by Game Scores'!E65:E67) -> 0 | F25: =SUM('Opponent Game by Game Scores'!F65:F67) -> 0 | G25: =SUM('Opponent Game by Game Scores'!G65:G67) -> 0 | J25: Week 21 | K25: =SUM('Opponent Game by Game Scores'!K65:K67) -> 0 | L25: =SUM('Opponent Game by Game Scores'!L65:L67) -> 0 | M25: =SUM('Opponent Game by Game Scores'!M65:M67) -> 0 | N25: =SUM('Opponent Game by Game Scores'!N65:N67) -> 0 | O25: =SUM('Opponent Game by Game Scores'!O65:O67) -> 0 | P25: =SUM('Opponent Game by Game Scores'!P65:P67) -> 0
A26: Week 22 | B26: =SUM('Opponent Game by Game Scores'!B68:B70) -> 0 | C26: =SUM('Opponent Game by Game Scores'!C68:C70) -> 0 | D26: =SUM('Opponent Game by Game Scores'!D68:D70) -> 0 | E26: =SUM('Opponent Game by Game Scores'!E68:E70) -> 0 | F26: =SUM('Opponent Game by Game Scores'!F68:F70) -> 0 | G26: =SUM('Opponent Game by Game Scores'!G68:G70) -> 0 | J26: Week 22 | K26: =SUM('Opponent Game by Game Scores'!K68:K70) -> 0 | L26: =SUM('Opponent Game by Game Scores'!L68:L70) -> 0 | M26: =SUM('Opponent Game by Game Scores'!M68:M70) -> 0 | N26: =SUM('Opponent Game by Game Scores'!N68:N70) -> 0 | O26: =SUM('Opponent Game by Game Scores'!O68:O70) -> 0 | P26: =SUM('Opponent Game by Game Scores'!P68:P70) -> 0
A27: Week 23 | B27: =SUM('Opponent Game by Game Scores'!B71:B73) -> 0 | C27: =SUM('Opponent Game by Game Scores'!C71:C73) -> 0 | D27: =SUM('Opponent Game by Game Scores'!D71:D73) -> 0 | E27: =SUM('Opponent Game by Game Scores'!E71:E73) -> 0 | F27: =SUM('Opponent Game by Game Scores'!F71:F73) -> 0 | G27: =SUM('Opponent Game by Game Scores'!G71:G73) -> 0 | J27: Week 23 | K27: =SUM('Opponent Game by Game Scores'!K71:K73) -> 0 | L27: =SUM('Opponent Game by Game Scores'!L71:L73) -> 0 | M27: =SUM('Opponent Game by Game Scores'!M71:M73) -> 0 | N27: =SUM('Opponent Game by Game Scores'!N71:N73) -> 0 | O27: =SUM('Opponent Game by Game Scores'!O71:O73) -> 0 | P27: =SUM('Opponent Game by Game Scores'!P71:P73) -> 0
A28: Week 24 | B28: =SUM('Opponent Game by Game Scores'!B74:B76) -> 0 | C28: =SUM('Opponent Game by Game Scores'!C74:C76) -> 0 | D28: =SUM('Opponent Game by Game Scores'!D74:D76) -> 0 | E28: =SUM('Opponent Game by Game Scores'!E74:E76) -> 0 | F28: =SUM('Opponent Game by Game Scores'!F74:F76) -> 0 | G28: =SUM('Opponent Game by Game Scores'!G74:G76) -> 0 | J28: Week 24 | K28: =SUM('Opponent Game by Game Scores'!K74:K76) -> 0 | L28: =SUM('Opponent Game by Game Scores'!L74:L76) -> 0 | M28: =SUM('Opponent Game by Game Scores'!M74:M76) -> 0 | N28: =SUM('Opponent Game by Game Scores'!N74:N76) -> 0 | O28: =SUM('Opponent Game by Game Scores'!O74:O76) -> 0 | P28: =SUM('Opponent Game by Game Scores'!P74:P76) -> 0
A29: Week 25 | B29: =SUM('Opponent Game by Game Scores'!B77:B79) -> 0 | C29: =SUM('Opponent Game by Game Scores'!C77:C79) -> 0 | D29: =SUM('Opponent Game by Game Scores'!D77:D79) -> 0 | E29: =SUM('Opponent Game by Game Scores'!E77:E79) -> 0 | F29: =SUM('Opponent Game by Game Scores'!F77:F79) -> 0 | G29: =SUM('Opponent Game by Game Scores'!G77:G79) -> 0 | J29: Week 25 | K29: =SUM('Opponent Game by Game Scores'!K77:K79) -> 0 | L29: =SUM('Opponent Game by Game Scores'!L77:L79) -> 0 | M29: =SUM('Opponent Game by Game Scores'!M77:M79) -> 0 | N29: =SUM('Opponent Game by Game Scores'!N77:N79) -> 0 | O29: =SUM('Opponent Game by Game Scores'!O77:O79) -> 0 | P29: =SUM('Opponent Game by Game Scores'!P77:P79) -> 0
A30: Week 26 | B30: =SUM('Opponent Game by Game Scores'!B80:B82) -> 0 | C30: =SUM('Opponent Game by Game Scores'!C80:C82) -> 0 | D30: =SUM('Opponent Game by Game Scores'!D80:D82) -> 0 | E30: =SUM('Opponent Game by Game Scores'!E80:E82) -> 0 | F30: =SUM('Opponent Game by Game Scores'!F80:F82) -> 0 | G30: =SUM('Opponent Game by Game Scores'!G80:G82) -> 0 | J30: Week 26 | K30: =SUM('Opponent Game by Game Scores'!K80:K82) -> 0 | L30: =SUM('Opponent Game by Game Scores'!L80:L82) -> 0 | M30: =SUM('Opponent Game by Game Scores'!M80:M82) -> 0 | N30: =SUM('Opponent Game by Game Scores'!N80:N82) -> 0 | O30: =SUM('Opponent Game by Game Scores'!O80:O82) -> 0 | P30: =SUM('Opponent Game by Game Scores'!P80:P82) -> 0
A31: Week 27 | B31: =SUM('Opponent Game by Game Scores'!B83:B85) -> 0 | C31: =SUM('Opponent Game by Game Scores'!C83:C85) -> 0 | D31: =SUM('Opponent Game by Game Scores'!D83:D85) -> 0 | E31: =SUM('Opponent Game by Game Scores'!E83:E85) -> 0 | F31: =SUM('Opponent Game by Game Scores'!F83:F85) -> 0 | G31: =SUM('Opponent Game by Game Scores'!G83:G85) -> 0 | J31: Week 27 | K31: =SUM('Opponent Game by Game Scores'!K83:K85) -> 0 | L31: =SUM('Opponent Game by Game Scores'!L83:L85) -> 0 | M31: =SUM('Opponent Game by Game Scores'!M83:M85) -> 0 | N31: =SUM('Opponent Game by Game Scores'!N83:N85) -> 0 | O31: =SUM('Opponent Game by Game Scores'!O83:O85) -> 0 | P31: =SUM('Opponent Game by Game Scores'!P83:P85) -> 0
A32: Week 28 | B32: =SUM('Opponent Game by Game Scores'!B86:B88) -> 0 | C32: =SUM('Opponent Game by Game Scores'!C86:C88) -> 0 | D32: =SUM('Opponent Game by Game Scores'!D86:D88) -> 0 | E32: =SUM('Opponent Game by Game Scores'!E86:E88) -> 0 | F32: =SUM('Opponent Game by Game Scores'!F86:F88) -> 0 | G32: =SUM('Opponent Game by Game Scores'!G86:G88) -> 0 | J32: Week 28 | K32: =SUM('Opponent Game by Game Scores'!K86:K88) -> 0 | L32: =SUM('Opponent Game by Game Scores'!L86:L88) -> 0 | M32: =SUM('Opponent Game by Game Scores'!M86:M88) -> 0 | N32: =SUM('Opponent Game by Game Scores'!N86:N88) -> 0 | O32: =SUM('Opponent Game by Game Scores'!O86:O88) -> 0 | P32: =SUM('Opponent Game by Game Scores'!P86:P88) -> 0
A33: Week 29 | B33: =SUM('Opponent Game by Game Scores'!B89:B91) -> 0 | C33: =SUM('Opponent Game by Game Scores'!C89:C91) -> 0 | D33: =SUM('Opponent Game by Game Scores'!D89:D91) -> 0 | E33: =SUM('Opponent Game by Game Scores'!E89:E91) -> 0 | F33: =SUM('Opponent Game by Game Scores'!F89:F91) -> 0 | G33: =SUM('Opponent Game by Game Scores'!G89:G91) -> 0 | J33: Week 29 | K33: =SUM('Opponent Game by Game Scores'!K89:K91) -> 0 | L33: =SUM('Opponent Game by Game Scores'!L89:L91) -> 0 | M33: =SUM('Opponent Game by Game Scores'!M89:M91) -> 0 | N33: =SUM('Opponent Game by Game Scores'!N89:N91) -> 0 | O33: =SUM('Opponent Game by Game Scores'!O89:O91) -> 0 | P33: =SUM('Opponent Game by Game Scores'!P89:P91) -> 0
A34: Week 30 | B34: =SUM('Opponent Game by Game Scores'!B92:B94) -> 0 | C34: =SUM('Opponent Game by Game Scores'!C92:C94) -> 0 | D34: =SUM('Opponent Game by Game Scores'!D92:D94) -> 0 | E34: =SUM('Opponent Game by Game Scores'!E92:E94) -> 0 | F34: =SUM('Opponent Game by Game Scores'!F92:F94) -> 0 | G34: =SUM('Opponent Game by Game Scores'!G92:G94) -> 0 | J34: Week 30 | K34: =SUM('Opponent Game by Game Scores'!K92:K94) -> 0 | L34: =SUM('Opponent Game by Game Scores'!L92:L94) -> 0 | M34: =SUM('Opponent Game by Game Scores'!M92:M94) -> 0 | N34: =SUM('Opponent Game by Game Scores'!N92:N94) -> 0 | O34: =SUM('Opponent Game by Game Scores'!O92:O94) -> 0 | P34: =SUM('Opponent Game by Game Scores'!P92:P94) -> 0
A35: Week 31 | B35: =SUM('Opponent Game by Game Scores'!B95:B97) -> 0 | C35: =SUM('Opponent Game by Game Scores'!C95:C97) -> 0 | D35: =SUM('Opponent Game by Game Scores'!D95:D97) -> 0 | E35: =SUM('Opponent Game by Game Scores'!E95:E97) -> 0 | F35: =SUM('Opponent Game by Game Scores'!F95:F97) -> 0 | G35: =SUM('Opponent Game by Game Scores'!G95:G97) -> 0 | J35: Week 31 | K35: =SUM('Opponent Game by Game Scores'!K95:K97) -> 0 | L35: =SUM('Opponent Game by Game Scores'!L95:L97) -> 0 | M35: =SUM('Opponent Game by Game Scores'!M95:M97) -> 0 | N35: =SUM('Opponent Game by Game Scores'!N95:N97) -> 0 | O35: =SUM('Opponent Game by Game Scores'!O95:O97) -> 0 | P35: =SUM('Opponent Game by Game Scores'!P95:P97) -> 0
